// Generated by CoffeeScript 1.12.4

/* exceptions.js */

(function() {
  var e, x;

  try {
    x = y * 64;
    console.log("The value of x is: " + x);
  } catch (error) {
    e = error;
    console.log("\nThe STACKTRACE for the exception/error:");
    console.log(e.stack);
  } finally {
    console.log("\nThis is the statement of finally block.");
  }

}).call(this);
