// Generated by CoffeeScript 2.2.2
// exceptions.coffee
var a, b, c, e, myFunc, x;

try {
  
  //y = 2
  /* exceptions.js */
  x = y * 64;
  console.log("The value of x is: " + x);
} catch (error) {
  e = error;
  console.log("\nThe STACKTRACE for the exception/error:");
  console.log(e.stack);
} finally {
  console.log("\nThis is the statement execution of finally block.");
  myFunc = function() {};
  a = 100;
  b = 0;
  try {
    if (b === 0) {
      throw "Divided by zero error";
    } else {
      c = a / b;
    }
  } catch (error) {
    e = error;
    console.log(e);
  }
}

myFunc();
